Workbook

Sheet ReadMe
A1: Inputs for a Toxicokinetic Model Predicting PFAS Chemicals in Blood Serum from Drinking Water Exposure
A3: This purpose of this model is to calculate the amount of PFAS in the serum of a population, given their tap water concentration over time and characteristics of the population.
A4: It can combine multiple exposure scenarios to determine what value of an independent variable would result in a population metric reaching a given serum threshold.
A6: Tab Name | B6: Tab Description
A7: ReadMe | B7: Describes the inputs in each tab, along with formatting requirements for these inputs
A8: Scenario | B8: Sets up model runs with parameters most commonly changed between scenarios, such as water concentrations and dates of interest
A9: ScenSummary | B9: Generates informative names for the exposure scenarios. Defines the independent variable information for projections - chemical, water concentration, age, etc.
A10: FitDistInfo | B10: Provides information for fitting distributions to selected scenarios and dates. Generates informative names for these fits so they can be referenced as maternal serum distributions in other Sets.
A11: ProjectionInfo | B11: Defines which projections should be made. Each projection uses the named exposure scenarios, an independent variable, a population metric, and a serum threshold.
A12: AgeInfo | B12: Defines optional receptor age distributions
A13: MonteCarlo | B13: Defines many distributional model parameters, such as half-life and volume of distribution
A14: DWI | B14: Defines mean weight-adjusted drinking water intake by age
A15: BkgdSerum | B15: Defines 'background' serum PFAS distributions by date, gender, and 'adult' or 'child' status
A16: MatSerum | B16: Contains information on maternal serum PFAS. Provides maternal 'background' serum for steady-state estimate and lookup information if using a parametric distribution.
A17: AltParams | B17: Sets alternate parameters by scenario name
A18: EvalInfo | B18: Table for observed data when evaluating model; documentation incomplete
A21: General Notes
A22: R is generally case-sensitive, meaning it does not read capital and lowercase letters as the same. Be aware of the capitalization of inputs and follow case exactly where specified to avoid errors.
A23: Excel formulae can be used to generate values. The final value will be input into the model, not the original formula
A24: Cells may need to begin with a single apostrophe (') to avoid inappropriate format conversions. I call this a 'leading apostrophe'
A25: A "string" is a term for alphabet characters, as a data entry type. Combinations of letters and numbers, such as 'Serum90p', will typically be read as a string in R.
A26: A "numeric" is a term for numbers, as a data entry type.
A27: Do not change column names in this spreadsheet. If the name is changed, the entries will not be read correctly.
A28: R converts tabs in the spreadsheet into an object type called a 'dataframe'. All entries in a column in a dataframe become the same class, for example string, numeric, date, logical...
A29: So if strings appear in a column that generally contains numerics, it may affect the ability of R to read the rest of the column entries correctly as numerics.
A30: Blank cells are sometimes important. Blank cells read as a true NA in R, in whatever class the column uses.
A33: Distribution Options
A34: The function make_rnd() generates random numbers for use as distributional parameters in each of the model iterations.
... A40: An example of this can be found in MonteCarlo tab in the Variable DWIaf_Teen, which uses a gamma distribution. This row uses the "Mean" and "Sd" columns to store the gamma distribution's shape and rate, respectively.
A42: Distribution Names | B42: Parm1 Definition | C42: Parm2 Definition | D42: Parm3 Definition
A43: Normal | B43: Arithmetic mean | C43: Arithmetic standard deviation
A44: Lognormal_geommean | B44: Geometric mean | C44: Geometric standard deviation
A45: Lognormal_meanlog | B45: Natural logarithm of the geometric mean | C45: Natural logarithm of the geometric standard deviation
A46: Weibull | B46: Shape | C46: Scale
A47: Gamma | B47: Shape | C47: Rate
A48: None | B48: Value
A49: Uniform | B49: Minimum | C49: Maximum
A50: Triangular | B50: Minimum | C50: Maximum | D50: Mode
A53: Scenario tab:
A54: Important notes
...

Sheet Scenario
A1: id | B1: filegroup | C1: chemical | D1: water_concs | E1: water_concs_dates | F1: water_concs_sds | G1: water_concs_dists | H1: mom_water_conc | I1: mom_serum_method | J1: gender | K1: fed_mo | L1: niter | M1: sd | N1: ed | O1: timezoom_start | P1: timezoom_end | Q1: timezoom_interval | R1: saved_dates
A2: =ScenSummary!A2 -> Set57_ES001_MdlMom_M_6moBF_PFOA_4 | B2: =_xlfn.TEXTJOIN("_",TRUE,ScenSummary!G2,ScenSummary!E2) -> PFOA_M | C2: PFOA | D2: 4 | E2: 1950-01-01 | F2: 0 | G2: None | H2: Set56_ES001_40yo_bf3SSmom_PFOA_4 | I2: logspline | J2: Male | K2: 6 | L2: 35000 | M2: 2025-01-01 | N2: 2095-01-01 | O2: 2026-01-01 | P2: 2035-01-01 | Q2: 1 month | R2: all
A3: =ScenSummary!A3 -> Set57_ES002_MdlMom_M_6moBF_PFOA_10 | B3: =_xlfn.TEXTJOIN("_",TRUE,ScenSummary!G3,ScenSummary!E3) -> PFOA_M | C3: PFOA | D3: 10 | E3: 1950-01-01 | F3: 0 | G3: None | H3: Set56_ES002_40yo_bf3SSmom_PFOA_10 | I3: logspline | J3: Male | K3: 6 | L3: 35000 | M3: 2025-01-01 | N3: 2095-01-01 | O3: 2026-01-01 | P3: 2035-01-01 | Q3: 1 month | R3: all
A4: =ScenSummary!A4 -> Set57_ES003_MdlMom_M_6moBF_PFOA_20 | B4: =_xlfn.TEXTJOIN("_",TRUE,ScenSummary!G4,ScenSummary!E4) -> PFOA_M | C4: PFOA | D4: 20 | E4: 1950-01-01 | F4: 0 | G4: None | H4: Set56_ES003_40yo_bf3SSmom_PFOA_20 | I4: logspline | J4: Male | K4: 6 | L4: 35000 | M4: 2025-01-01 | N4: 2095-01-01 | O4: 2026-01-01 | P4: 2035-01-01 | Q4: 1 month | R4: all
A5: =ScenSummary!A5 -> Set57_ES004_MdlMom_M_6moBF_PFOA_30 | B5: =_xlfn.TEXTJOIN("_",TRUE,ScenSummary!G5,ScenSummary!E5) -> PFOA_M | C5: PFOA | D5: 30 | E5: 1950-01-01 | F5: 0 | G5: None | H5: Set56_ES004_40yo_bf3SSmom_PFOA_30 | I5: logspline | J5: Male | K5: 6 | L5: 35000 | M5: 2025-01-01 | N5: 2095-01-01 | O5: 2026-01-01 | P5: 2035-01-01 | Q5: 1 month | R5: all
A6: =ScenSummary!A6 -> Set57_ES005_MdlMom_M_6moBF_PFOA_40 | B6: =_xlfn.TEXTJOIN("_",TRUE,ScenSummary!G6,ScenSummary!E6) -> PFOA_M | C6: PFOA | D6: 40 | E6: 1950-01-01 | F6: 0 | G6: None | H6: Set56_ES005_40yo_bf3SSmom_PFOA_40 | I6: logspline | J6: Male | K6: 6 | L6: 35000 | M6: 2025-01-01 | N6: 2095-01-01 | O6: 2026-01-01 | P6: 2035-01-01 | Q6: 1 month | R6: all
A7: =ScenSummary!A7 -> Set57_ES006_MdlMom_M_6moBF_PFOA_50 | B7: =_xlfn.TEXTJOIN("_",TRUE,ScenSummary!G7,ScenSummary!E7) -> PFOA_M | C7: PFOA | D7: 50 | E7: 1950-01-01 | F7: 0 | G7: None | H7: Set56_ES006_40yo_bf3SSmom_PFOA_50 | I7: logspline | J7: Male | K7: 6 | L7: 35000 | M7: 2025-01-01 | N7: 2095-01-01 | O7: 2026-01-01 | P7: 2035-01-01 | Q7: 1 month | R7: all
A8: =ScenSummary!A8 -> Set57_ES007_MdlMom_M_6moBF_PFOA_60 | B8: =_xlfn.TEXTJOIN("_",TRUE,ScenSummary!G8,ScenSummary!E8) -> PFOA_M | C8: PFOA | D8: 60 | E8: 1950-01-01 | F8: 0 | G8: None | H8: Set56_ES007_40yo_bf3SSmom_PFOA_60 | I8: logspline | J8: Male | K8: 6 | L8: 35000 | M8: 2025-01-01 | N8: 2095-01-01 | O8: 2026-01-01 | P8: 2035-01-01 | Q8: 1 month | R8: all
A9: =ScenSummary!A9 -> Set57_ES008_MdlMom_M_6moBF_PFOA_70 | B9: =_xlfn.TEXTJOIN("_",TRUE,ScenSummary!G9,ScenSummary!E9) -> PFOA_M | C9: PFOA | D9: 70 | E9: 1950-01-01 | F9: 0 | G9: None | H9: Set56_ES008_40yo_bf3SSmom_PFOA_70 | I9: logspline | J9: Male | K9: 6 | L9: 35000 | M9: 2025-01-01 | N9: 2095-01-01 | O9: 2026-01-01 | P9: 2035-01-01 | Q9: 1 month | R9: all
A10: =ScenSummary!A10 -> Set57_ES009_MdlMom_M_6moBF_PFOA_80 | B10: =_xlfn.TEXTJOIN("_",TRUE,ScenSummary!G10,ScenSummary!E10) -> PFOA_M | C10: PFOA | D10: 80 | E10: 1950-01-01 | F10: 0 | G10: None | H10: Set56_ES009_40yo_bf3SSmom_PFOA_80 | I10: logspline | J10: Male | K10: 6 | L10: 35000 | M10: 2025-01-01 | N10: 2095-01-01 | O10: 2026-01-01 | P10: 2035-01-01 | Q10: 1 month | R10: all
A11: =ScenSummary!A11 -> Set57_ES010_MdlMom_M_6moBF_PFOA_90 | B11: =_xlfn.TEXTJOIN("_",TRUE,ScenSummary!G11,ScenSummary!E11) -> PFOA_M | C11: PFOA | D11: 90 | E11: 1950-01-01 | F11: 0 | G11: None | H11: Set56_ES010_40yo_bf3SSmom_PFOA_90 | I11: logspline | J11: Male | K11: 6 | L11: 35000 | M11: 2025-01-01 | N11: 2095-01-01 | O11: 2026-01-01 | P11: 2035-01-01 | Q11: 1 month | R11: all
A12: =ScenSummary!A12 -> Set57_ES011_MdlMom_M_6moBF_PFOS_4 | B12: =_xlfn.TEXTJOIN("_",TRUE,ScenSummary!G12,ScenSummary!E12) -> PFOS_M | C12: PFOS | D12: 4 | E12: 1950-01-01 | F12: 0 | G12: None | H12: Set56_ES011_40yo_bf3SSmom_PFOS_4 | I12: logspline | J12: Male | K12: 6 | L12: 35000 | M12: 2025-01-01 | N12: 2095-01-01 | O12: 2026-01-01 | P12: 2035-01-01 | Q12: 1 month | R12: all
A13: =ScenSummary!A13 -> Set57_ES012_MdlMom_M_6moBF_PFOS_10 | B13: =_xlfn.TEXTJOIN("_",TRUE,ScenSummary!G13,ScenSummary!E13) -> PFOS_M | C13: PFOS | D13: 10 | E13: 1950-01-01 | F13: 0 | G13: None | H13: Set56_ES012_40yo_bf3SSmom_PFOS_10 | I13: logspline | J13: Male | K13: 6 | L13: 35000 | M13: 2025-01-01 | N13: 2095-01-01 | O13: 2026-01-01 | P13: 2035-01-01 | Q13: 1 month | R13: all
... A61: =ScenSummary!A61 -> Set57_ES060_MdlMom_M_6moBF_PFHpA_90 | B61: =_xlfn.TEXTJOIN("_",TRUE,ScenSummary!G61,ScenSummary!E61) -> PFHpA_M | C61: PFHpA | D61: 90 | E61: 1950-01-01 | F61: 0 | G61: None | H61: Set56_ES060_40yo_bf3SSmom_PFHpA_90 | I61: logspline | J61: Male | K61: 6 | L61: 35000 | M61: 2025-01-01 | N61: 2095-01-01 | O61: 2026-01-01 | P61: 2035-01-01 | Q61: 1 month | R61: all

Sheet ScenSummary
A1: ScenID | B1: SetNum | C1: ESNum | D1: MomType | E1: Gender | F1: MonthsBreastfed | G1: Chemical | H1: WaterConc
A2: =_xlfn.TEXTJOIN("_",TRUE,B2:H2) -> Set57_ES001_MdlMom_M_6moBF_PFOA_4 | B2: Set57 | C2: ES001 | D2: MdlMom | E2: M | F2: 6moBF | G2: PFOA | H2: 4
A3: =_xlfn.TEXTJOIN("_",TRUE,B3:H3) -> Set57_ES002_MdlMom_M_6moBF_PFOA_10 | B3: Set57 | C3: ES002 | D3: MdlMom | E3: M | F3: 6moBF | G3: PFOA | H3: 10
A4: =_xlfn.TEXTJOIN("_",TRUE,B4:H4) -> Set57_ES003_MdlMom_M_6moBF_PFOA_20 | B4: Set57 | C4: ES003 | D4: MdlMom | E4: M | F4: 6moBF | G4: PFOA | H4: 20
A5: =_xlfn.TEXTJOIN("_",TRUE,B5:H5) -> Set57_ES004_MdlMom_M_6moBF_PFOA_30 | B5: Set57 | C5: ES004 | D5: MdlMom | E5: M | F5: 6moBF | G5: PFOA | H5: 30
A6: =_xlfn.TEXTJOIN("_",TRUE,B6:H6) -> Set57_ES005_MdlMom_M_6moBF_PFOA_40 | B6: Set57 | C6: ES005 | D6: MdlMom | E6: M | F6: 6moBF | G6: PFOA | H6: 40
A7: =_xlfn.TEXTJOIN("_",TRUE,B7:H7) -> Set57_ES006_MdlMom_M_6moBF_PFOA_50 | B7: Set57 | C7: ES006 | D7: MdlMom | E7: M | F7: 6moBF | G7: PFOA | H7: 50
A8: =_xlfn.TEXTJOIN("_",TRUE,B8:H8) -> Set57_ES007_MdlMom_M_6moBF_PFOA_60 | B8: Set57 | C8: ES007 | D8: MdlMom | E8: M | F8: 6moBF | G8: PFOA | H8: 60
A9: =_xlfn.TEXTJOIN("_",TRUE,B9:H9) -> Set57_ES008_MdlMom_M_6moBF_PFOA_70 | B9: Set57 | C9: ES008 | D9: MdlMom | E9: M | F9: 6moBF | G9: PFOA | H9: 70
A10: =_xlfn.TEXTJOIN("_",TRUE,B10:H10) -> Set57_ES009_MdlMom_M_6moBF_PFOA_80 | B10: Set57 | C10: ES009 | D10: MdlMom | E10: M | F10: 6moBF | G10: PFOA | H10: 80
A11: =_xlfn.TEXTJOIN("_",TRUE,B11:H11) -> Set57_ES010_MdlMom_M_6moBF_PFOA_90 | B11: Set57 | C11: ES010 | D11: MdlMom | E11: M | F11: 6moBF | G11: PFOA | H11: 90
A12: =_xlfn.TEXTJOIN("_",TRUE,B12:H12) -> Set57_ES011_MdlMom_M_6moBF_PFOS_4 | B12: Set57 | C12: ES011 | D12: MdlMom | E12: M | F12: 6moBF | G12: PFOS | H12: 4
A13: =_xlfn.TEXTJOIN("_",TRUE,B13:H13) -> Set57_ES012_MdlMom_M_6moBF_PFOS_10 | B13: Set57 | C13: ES012 | D13: MdlMom | E13: M | F13: 6moBF | G13: PFOS | H13: 10
... A61: =_xlfn.TEXTJOIN("_",TRUE,B61:H61) -> Set57_ES060_MdlMom_M_6moBF_PFHpA_90 | B61: Set57 | C61: ES060 | D61: MdlMom | E61: M | F61: 6moBF | G61: PFHpA | H61: 90

Sheet FitDistInfo
A1: ScenID | B1: Date | C1: FitType | D1: DistributionID | E1: SetNum | F1: ESNum | G1: Age | H1: ParmAbbr | I1: Chemical | J1: WaterConc

Sheet ProjectionInfo
A1: ProjID | B1: ScenIDs | C1: IndependentVar | D1: SerumThreshold | E1: Percentile | F1: Date | G1: RegressionType | H1: Age | I1: Chemical | J1: Gender | K1: MomType | L1: MonthsBreastfed | M1: InfantResolution
A2: PJ01 | B2: =_xlfn.TEXTJOIN(",",TRUE,Scenario!$A$2:$A$11) -> Set57_ES001_MdlMom_M_6moBF_PFOA_4,Set57_ES002_MdlMom_M_6moBF_PFOA_10,Set57_ES003_MdlMom_M_6moBF_PFOA_20,Set57_ES004_MdlMom_M_6moBF_PFOA_30,Set57_ES005_MdlMom_M_6moBF_PFOA_40,Set57_ES006_MdlMom_M_6moBF_PFOA_50,Set57_ES007_MdlMom_M_6moBF_PFOA_60,Set57_ES008_MdlMom_M_6moBF_PFOA_70,Set57_ES009_MdlMom_M_6moBF_PFOA_80,Set57_ES010_MdlMom_M_6moBF_PFOA_90 | C2: WaterConc | D2: 20 | E2: 90 | F2: 2025-07-01 | G2: Linear | H2: 0.5 | I2: PFOA | J2: M | K2: MdlMom | L2: 6 | M2: MoRes
A3: PJ02 | B3: =_xlfn.TEXTJOIN(",",TRUE,Scenario!$A$12:$A$21) -> Set57_ES011_MdlMom_M_6moBF_PFOS_4,Set57_ES012_MdlMom_M_6moBF_PFOS_10,Set57_ES013_MdlMom_M_6moBF_PFOS_20,Set57_ES014_MdlMom_M_6moBF_PFOS_30,Set57_ES015_MdlMom_M_6moBF_PFOS_40,Set57_ES016_MdlMom_M_6moBF_PFOS_50,Set57_ES017_MdlMom_M_6moBF_PFOS_60,Set57_ES018_MdlMom_M_6moBF_PFOS_70,Set57_ES019_MdlMom_M_6moBF_PFOS_80,Set57_ES020_MdlMom_M_6moBF_PFOS_90 | C3: WaterConc | D3: 20 | E3: 90 | F3: 2025-07-01 | G3: Linear | H3: 0.5 | I3: PFOS | J3: M | K3: MdlMom | L3: 6 | M3: MoRes
A4: PJ03 | B4: =_xlfn.TEXTJOIN(",",TRUE,Scenario!$A$22:$A$31) -> Set57_ES021_MdlMom_M_6moBF_PFHxS_4,Set57_ES022_MdlMom_M_6moBF_PFHxS_10,Set57_ES023_MdlMom_M_6moBF_PFHxS_20,Set57_ES024_MdlMom_M_6moBF_PFHxS_30,Set57_ES025_MdlMom_M_6moBF_PFHxS_40,Set57_ES026_MdlMom_M_6moBF_PFHxS_50,Set57_ES027_MdlMom_M_6moBF_PFHxS_60,Set57_ES028_MdlMom_M_6moBF_PFHxS_70,Set57_ES029_MdlMom_M_6moBF_PFHxS_80,Set57_ES030_MdlMom_M_6moBF_PFHxS_90 | C4: WaterConc | D4: 20 | E4: 90 | F4: 2025-07-01 | G4: Linear | H4: 0.5 | I4: PFHxS | J4: M | K4: MdlMom | L4: 6 | M4: MoRes
A5: PJ04 | B5: =_xlfn.TEXTJOIN(",",TRUE,Scenario!$A$32:$A$41) -> Set57_ES031_MdlMom_M_6moBF_PFNA_4,Set57_ES032_MdlMom_M_6moBF_PFNA_10,Set57_ES033_MdlMom_M_6moBF_PFNA_20,Set57_ES034_MdlMom_M_6moBF_PFNA_30,Set57_ES035_MdlMom_M_6moBF_PFNA_40,Set57_ES036_MdlMom_M_6moBF_PFNA_50,Set57_ES037_MdlMom_M_6moBF_PFNA_60,Set57_ES038_MdlMom_M_6moBF_PFNA_70,Set57_ES039_MdlMom_M_6moBF_PFNA_80,Set57_ES040_MdlMom_M_6moBF_PFNA_90 | C5: WaterConc | D5: 20 | E5: 90 | F5: 2025-07-01 | G5: Linear | H5: 0.5 | I5: PFNA | J5: M | K5: MdlMom | L5: 6 | M5: MoRes
A6: PJ05 | B6: =_xlfn.TEXTJOIN(",",TRUE,Scenario!$A$42:$A$51) -> Set57_ES041_MdlMom_M_6moBF_PFDA_4,Set57_ES042_MdlMom_M_6moBF_PFDA_10,Set57_ES043_MdlMom_M_6moBF_PFDA_20,Set57_ES044_MdlMom_M_6moBF_PFDA_30,Set57_ES045_MdlMom_M_6moBF_PFDA_40,Set57_ES046_MdlMom_M_6moBF_PFDA_50,Set57_ES047_MdlMom_M_6moBF_PFDA_60,Set57_ES048_MdlMom_M_6moBF_PFDA_70,Set57_ES049_MdlMom_M_6moBF_PFDA_80,Set57_ES050_MdlMom_M_6moBF_PFDA_90 | C6: WaterConc | D6: 20 | E6: 90 | F6: 2025-07-01 | G6: Linear | H6: 0.5 | I6: PFDA | J6: M | K6: MdlMom | L6: 6 | M6: MoRes
A7: PJ06 | B7: =_xlfn.TEXTJOIN(",",TRUE,Scenario!$A$52:$A$61) -> Set57_ES051_MdlMom_M_6moBF_PFHpA_4,Set57_ES052_MdlMom_M_6moBF_PFHpA_10,Set57_ES053_MdlMom_M_6moBF_PFHpA_20,Set57_ES054_MdlMom_M_6moBF_PFHpA_30,Set57_ES055_MdlMom_M_6moBF_PFHpA_40,Set57_ES056_MdlMom_M_6moBF_PFHpA_50,Set57_ES057_MdlMom_M_6moBF_PFHpA_60,Set57_ES058_MdlMom_M_6moBF_PFHpA_70,Set57_ES059_MdlMom_M_6moBF_PFHpA_80,Set57_ES060_MdlMom_M_6moBF_PFHpA_90 | C7: WaterConc | D7: 20 | E7: 90 | F7: 2025-07-01 | G7: Linear | H7: 0.5 | I7: PFHpA | J7: M | K7: MdlMom | L7: 6 | M7: MoRes
A8: PJ07 | B8: =_xlfn.TEXTJOIN(",",TRUE,Scenario!$A$2:$A$11) -> Set57_ES001_MdlMom_M_6moBF_PFOA_4,Set57_ES002_MdlMom_M_6moBF_PFOA_10,Set57_ES003_MdlMom_M_6moBF_PFOA_20,Set57_ES004_MdlMom_M_6moBF_PFOA_30,Set57_ES005_MdlMom_M_6moBF_PFOA_40,Set57_ES006_MdlMom_M_6moBF_PFOA_50,Set57_ES007_MdlMom_M_6moBF_PFOA_60,Set57_ES008_MdlMom_M_6moBF_PFOA_70,Set57_ES009_MdlMom_M_6moBF_PFOA_80,Set57_ES010_MdlMom_M_6moBF_PFOA_90 | C8: WaterConc | D8: 20 | E8: 90 | F8: 2065-01-01 | G8: Linear | H8: 40 | I8: PFOA | J8: M | K8: MdlMom | L8: 6 | M8: MoRes
A9: PJ08 | B9: =_xlfn.TEXTJOIN(",",TRUE,Scenario!$A$12:$A$21) -> Set57_ES011_MdlMom_M_6moBF_PFOS_4,Set57_ES012_MdlMom_M_6moBF_PFOS_10,Set57_ES013_MdlMom_M_6moBF_PFOS_20,Set57_ES014_MdlMom_M_6moBF_PFOS_30,Set57_ES015_MdlMom_M_6moBF_PFOS_40,Set57_ES016_MdlMom_M_6moBF_PFOS_50,Set57_ES017_MdlMom_M_6moBF_PFOS_60,Set57_ES018_MdlMom_M_6moBF_PFOS_70,Set57_ES019_MdlMom_M_6moBF_PFOS_80,Set57_ES020_MdlMom_M_6moBF_PFOS_90 | C9: WaterConc | D9: 20 | E9: 90 | F9: 2065-01-01 | G9: Linear | H9: 40 | I9: PFOS | J9: M | K9: MdlMom | L9: 6 | M9: MoRes
A10: PJ09 | B10: =_xlfn.TEXTJOIN(",",TRUE,Scenario!$A$22:$A$31) -> Set57_ES021_MdlMom_M_6moBF_PFHxS_4,Set57_ES022_MdlMom_M_6moBF_PFHxS_10,Set57_ES023_MdlMom_M_6moBF_PFHxS_20,Set57_ES024_MdlMom_M_6moBF_PFHxS_30,Set57_ES025_MdlMom_M_6moBF_PFHxS_40,Set57_ES026_MdlMom_M_6moBF_PFHxS_50,Set57_ES027_MdlMom_M_6moBF_PFHxS_60,Set57_ES028_MdlMom_M_6moBF_PFHxS_70,Set57_ES029_MdlMom_M_6moBF_PFHxS_80,Set57_ES030_MdlMom_M_6moBF_PFHxS_90 | C10: WaterConc | D10: 20 | E10: 90 | F10: 2065-01-01 | G10: Linear | H10: 40 | I10: PFHxS | J10: M | K10: MdlMom | L10: 6 | M10: MoRes
A11: PJ10 | B11: =_xlfn.TEXTJOIN(",",TRUE,Scenario!$A$32:$A$41) -> Set57_ES031_MdlMom_M_6moBF_PFNA_4,Set57_ES032_MdlMom_M_6moBF_PFNA_10,Set57_ES033_MdlMom_M_6moBF_PFNA_20,Set57_ES034_MdlMom_M_6moBF_PFNA_30,Set57_ES035_MdlMom_M_6moBF_PFNA_40,Set57_ES036_MdlMom_M_6moBF_PFNA_50,Set57_ES037_MdlMom_M_6moBF_PFNA_60,Set57_ES038_MdlMom_M_6moBF_PFNA_70,Set57_ES039_MdlMom_M_6moBF_PFNA_80,Set57_ES040_MdlMom_M_6moBF_PFNA_90 | C11: WaterConc | D11: 20 | E11: 90 | F11: 2065-01-01 | G11: Linear | H11: 40 | I11: PFNA | J11: M | K11: MdlMom | L11: 6 | M11: MoRes
A12: PJ11 | B12: =_xlfn.TEXTJOIN(",",TRUE,Scenario!$A$42:$A$51) -> Set57_ES041_MdlMom_M_6moBF_PFDA_4,Set57_ES042_MdlMom_M_6moBF_PFDA_10,Set57_ES043_MdlMom_M_6moBF_PFDA_20,Set57_ES044_MdlMom_M_6moBF_PFDA_30,Set57_ES045_MdlMom_M_6moBF_PFDA_40,Set57_ES046_MdlMom_M_6moBF_PFDA_50,Set57_ES047_MdlMom_M_6moBF_PFDA_60,Set57_ES048_MdlMom_M_6moBF_PFDA_70,Set57_ES049_MdlMom_M_6moBF_PFDA_80,Set57_ES050_MdlMom_M_6moBF_PFDA_90 | C12: WaterConc | D12: 20 | E12: 90 | F12: 2065-01-01 | G12: Linear | H12: 40 | I12: PFDA | J12: M | K12: MdlMom | L12: 6 | M12: MoRes
A13: PJ12 | B13: =_xlfn.TEXTJOIN(",",TRUE,Scenario!$A$52:$A$61) -> Set57_ES051_MdlMom_M_6moBF_PFHpA_4,Set57_ES052_MdlMom_M_6moBF_PFHpA_10,Set57_ES053_MdlMom_M_6moBF_PFHpA_20,Set57_ES054_MdlMom_M_6moBF_PFHpA_30,Set57_ES055_MdlMom_M_6moBF_PFHpA_40,Set57_ES056_MdlMom_M_6moBF_PFHpA_50,Set57_ES057_MdlMom_M_6moBF_PFHpA_60,Set57_ES058_MdlMom_M_6moBF_PFHpA_70,Set57_ES059_MdlMom_M_6moBF_PFHpA_80,Set57_ES060_MdlMom_M_6moBF_PFHpA_90 | C13: WaterConc | D13: 20 | E13: 90 | F13: 2065-01-01 | G13: Linear | H13: 40 | I13: PFHpA | J13: M | K13: MdlMom | L13: 6 | M13: MoRes
A14: PJ13 | B14: =_xlfn.TEXTJOIN(",",TRUE,Scenario!$A$2:$A$11) -> Set57_ES001_MdlMom_M_6moBF_PFOA_4,Set57_ES002_MdlMom_M_6moBF_PFOA_10,Set57_ES003_MdlMom_M_6moBF_PFOA_20,Set57_ES004_MdlMom_M_6moBF_PFOA_30,Set57_ES005_MdlMom_M_6moBF_PFOA_40,Set57_ES006_MdlMom_M_6moBF_PFOA_50,Set57_ES007_MdlMom_M_6moBF_PFOA_60,Set57_ES008_MdlMom_M_6moBF_PFOA_70,Set57_ES009_MdlMom_M_6moBF_PFOA_80,Set57_ES010_MdlMom_M_6moBF_PFOA_90 | C14: WaterConc | D14: 20 | E14: 90 | F14: 2095-01-01 | G14: Linear | H14: 70 | I14: PFOA | J14: M | K14: MdlMom | L14: 6 | M14: MoRes
A15: PJ14 | B15: =_xlfn.TEXTJOIN(",",TRUE,Scenario!$A$12:$A$21) -> Set57_ES011_MdlMom_M_6moBF_PFOS_4,Set57_ES012_MdlMom_M_6moBF_PFOS_10,Set57_ES013_MdlMom_M_6moBF_PFOS_20,Set57_ES014_MdlMom_M_6moBF_PFOS_30,Set57_ES015_MdlMom_M_6moBF_PFOS_40,Set57_ES016_MdlMom_M_6moBF_PFOS_50,Set57_ES017_MdlMom_M_6moBF_PFOS_60,Set57_ES018_MdlMom_M_6moBF_PFOS_70,Set57_ES019_MdlMom_M_6moBF_PFOS_80,Set57_ES020_MdlMom_M_6moBF_PFOS_90 | C15: WaterConc | D15: 20 | E15: 90 | F15: 2095-01-01 | G15: Linear | H15: 70 | I15: PFOS | J15: M | K15: MdlMom | L15: 6 | M15: MoRes
A16: PJ15 | B16: =_xlfn.TEXTJOIN(",",TRUE,Scenario!$A$22:$A$31) -> Set57_ES021_MdlMom_M_6moBF_PFHxS_4,Set57_ES022_MdlMom_M_6moBF_PFHxS_10,Set57_ES023_MdlMom_M_6moBF_PFHxS_20,Set57_ES024_MdlMom_M_6moBF_PFHxS_30,Set57_ES025_MdlMom_M_6moBF_PFHxS_40,Set57_ES026_MdlMom_M_6moBF_PFHxS_50,Set57_ES027_MdlMom_M_6moBF_PFHxS_60,Set57_ES028_MdlMom_M_6moBF_PFHxS_70,Set57_ES029_MdlMom_M_6moBF_PFHxS_80,Set57_ES030_MdlMom_M_6moBF_PFHxS_90 | C16: WaterConc | D16: 20 | E16: 90 | F16: 2095-01-01 | G16: Linear | H16: 70 | I16: PFHxS | J16: M | K16: MdlMom | L16: 6 | M16: MoRes
A17: PJ16 | B17: =_xlfn.TEXTJOIN(",",TRUE,Scenario!$A$32:$A$41) -> Set57_ES031_MdlMom_M_6moBF_PFNA_4,Set57_ES032_MdlMom_M_6moBF_PFNA_10,Set57_ES033_MdlMom_M_6moBF_PFNA_20,Set57_ES034_MdlMom_M_6moBF_PFNA_30,Set57_ES035_MdlMom_M_6moBF_PFNA_40,Set57_ES036_MdlMom_M_6moBF_PFNA_50,Set57_ES037_MdlMom_M_6moBF_PFNA_60,Set57_ES038_MdlMom_M_6moBF_PFNA_70,Set57_ES039_MdlMom_M_6moBF_PFNA_80,Set57_ES040_MdlMom_M_6moBF_PFNA_90 | C17: WaterConc | D17: 20 | E17: 90 | F17: 2095-01-01 | G17: Linear | H17: 70 | I17: PFNA | J17: M | K17: MdlMom | L17: 6 | M17: MoRes
A18: PJ17 | B18: =_xlfn.TEXTJOIN(",",TRUE,Scenario!$A$42:$A$51) -> Set57_ES041_MdlMom_M_6moBF_PFDA_4,Set57_ES042_MdlMom_M_6moBF_PFDA_10,Set57_ES043_MdlMom_M_6moBF_PFDA_20,Set57_ES044_MdlMom_M_6moBF_PFDA_30,Set57_ES045_MdlMom_M_6moBF_PFDA_40,Set57_ES046_MdlMom_M_6moBF_PFDA_50,Set57_ES047_MdlMom_M_6moBF_PFDA_60,Set57_ES048_MdlMom_M_6moBF_PFDA_70,Set57_ES049_MdlMom_M_6moBF_PFDA_80,Set57_ES050_MdlMom_M_6moBF_PFDA_90 | C18: WaterConc | D18: 20 | E18: 90 | F18: 2095-01-01 | G18: Linear | H18: 70 | I18: PFDA | J18: M | K18: MdlMom | L18: 6 | M18: MoRes
A19: PJ18 | B19: =_xlfn.TEXTJOIN(",",TRUE,Scenario!$A$52:$A$61) -> Set57_ES051_MdlMom_M_6moBF_PFHpA_4,Set57_ES052_MdlMom_M_6moBF_PFHpA_10,Set57_ES053_MdlMom_M_6moBF_PFHpA_20,Set57_ES054_MdlMom_M_6moBF_PFHpA_30,Set57_ES055_MdlMom_M_6moBF_PFHpA_40,Set57_ES056_MdlMom_M_6moBF_PFHpA_50,Set57_ES057_MdlMom_M_6moBF_PFHpA_60,Set57_ES058_MdlMom_M_6moBF_PFHpA_70,Set57_ES059_MdlMom_M_6moBF_PFHpA_80,Set57_ES060_MdlMom_M_6moBF_PFHpA_90 | C19: WaterConc | D19: 20 | E19: 90 | F19: 2095-01-01 | G19: Linear | H19: 70 | I19: PFHpA | J19: M | K19: MdlMom | L19: 6 | M19: MoRes
A20: PJ19 | B20: =_xlfn.TEXTJOIN(",",TRUE,Scenario!$A$2:$A$11) -> Set57_ES001_MdlMom_M_6moBF_PFOA_4,Set57_ES002_MdlMom_M_6moBF_PFOA_10,Set57_ES003_MdlMom_M_6moBF_PFOA_20,Set57_ES004_MdlMom_M_6moBF_PFOA_30,Set57_ES005_MdlMom_M_6moBF_PFOA_40,Set57_ES006_MdlMom_M_6moBF_PFOA_50,Set57_ES007_MdlMom_M_6moBF_PFOA_60,Set57_ES008_MdlMom_M_6moBF_PFOA_70,Set57_ES009_MdlMom_M_6moBF_PFOA_80,Set57_ES010_MdlMom_M_6moBF_PFOA_90 | C20: WaterConc | D20: 20 | E20: 75 | F20: 2025-07-01 | G20: Linear | H20: 0.5 | I20: PFOA | J20: M | K20: MdlMom | L20: 6 | M20: MoRes
A21: PJ20 | B21: =_xlfn.TEXTJOIN(",",TRUE,Scenario!$A$12:$A$21) -> Set57_ES011_MdlMom_M_6moBF_PFOS_4,Set57_ES012_MdlMom_M_6moBF_PFOS_10,Set57_ES013_MdlMom_M_6moBF_PFOS_20,Set57_ES014_MdlMom_M_6moBF_PFOS_30,Set57_ES015_MdlMom_M_6moBF_PFOS_40,Set57_ES016_MdlMom_M_6moBF_PFOS_50,Set57_ES017_MdlMom_M_6moBF_PFOS_60,Set57_ES018_MdlMom_M_6moBF_PFOS_70,Set57_ES019_MdlMom_M_6moBF_PFOS_80,Set57_ES020_MdlMom_M_6moBF_PFOS_90 | C21: WaterConc | D21: 20 | E21: 75 | F21: 2025-07-01 | G21: Linear | H21: 0.5 | I21: PFOS | J21: M | K21: MdlMom | L21: 6 | M21: MoRes
A22: PJ21 | B22: =_xlfn.TEXTJOIN(",",TRUE,Scenario!$A$22:$A$31) -> Set57_ES021_MdlMom_M_6moBF_PFHxS_4,Set57_ES022_MdlMom_M_6moBF_PFHxS_10,Set57_ES023_MdlMom_M_6moBF_PFHxS_20,Set57_ES024_MdlMom_M_6moBF_PFHxS_30,Set57_ES025_MdlMom_M_6moBF_PFHxS_40,Set57_ES026_MdlMom_M_6moBF_PFHxS_50,Set57_ES027_MdlMom_M_6moBF_PFHxS_60,Set57_ES028_MdlMom_M_6moBF_PFHxS_70,Set57_ES029_MdlMom_M_6moBF_PFHxS_80,Set57_ES030_MdlMom_M_6moBF_PFHxS_90 | C22: WaterConc | D22: 20 | E22: 75 | F22: 2025-07-01 | G22: Linear | H22: 0.5 | I22: PFHxS | J22: M | K22: MdlMom | L22: 6 | M22: MoRes
A23: PJ22 | B23: =_xlfn.TEXTJOIN(",",TRUE,Scenario!$A$32:$A$41) -> Set57_ES031_MdlMom_M_6moBF_PFNA_4,Set57_ES032_MdlMom_M_6moBF_PFNA_10,Set57_ES033_MdlMom_M_6moBF_PFNA_20,Set57_ES034_MdlMom_M_6moBF_PFNA_30,Set57_ES035_MdlMom_M_6moBF_PFNA_40,Set57_ES036_MdlMom_M_6moBF_PFNA_50,Set57_ES037_MdlMom_M_6moBF_PFNA_60,Set57_ES038_MdlMom_M_6moBF_PFNA_70,Set57_ES039_MdlMom_M_6moBF_PFNA_80,Set57_ES040_MdlMom_M_6moBF_PFNA_90 | C23: WaterConc | D23: 20 | E23: 75 | F23: 2025-07-01 | G23: Linear | H23: 0.5 | I23: PFNA | J23: M | K23: MdlMom | L23: 6 | M23: MoRes
A24: PJ23 | B24: =_xlfn.TEXTJOIN(",",TRUE,Scenario!$A$42:$A$51) -> Set57_ES041_MdlMom_M_6moBF_PFDA_4,Set57_ES042_MdlMom_M_6moBF_PFDA_10,Set57_ES043_MdlMom_M_6moBF_PFDA_20,Set57_ES044_MdlMom_M_6moBF_PFDA_30,Set57_ES045_MdlMom_M_6moBF_PFDA_40,Set57_ES046_MdlMom_M_6moBF_PFDA_50,Set57_ES047_MdlMom_M_6moBF_PFDA_60,Set57_ES048_MdlMom_M_6moBF_PFDA_70,Set57_ES049_MdlMom_M_6moBF_PFDA_80,Set57_ES050_MdlMom_M_6moBF_PFDA_90 | C24: WaterConc | D24: 20 | E24: 75 | F24: 2025-07-01 | G24: Linear | H24: 0.5 | I24: PFDA | J24: M | K24: MdlMom | L24: 6 | M24: MoRes
A25: PJ24 | B25: =_xlfn.TEXTJOIN(",",TRUE,Scenario!$A$52:$A$61) -> Set57_ES051_MdlMom_M_6moBF_PFHpA_4,Set57_ES052_MdlMom_M_6moBF_PFHpA_10,Set57_ES053_MdlMom_M_6moBF_PFHpA_20,Set57_ES054_MdlMom_M_6moBF_PFHpA_30,Set57_ES055_MdlMom_M_6moBF_PFHpA_40,Set57_ES056_MdlMom_M_6moBF_PFHpA_50,Set57_ES057_MdlMom_M_6moBF_PFHpA_60,Set57_ES058_MdlMom_M_6moBF_PFHpA_70,Set57_ES059_MdlMom_M_6moBF_PFHpA_80,Set57_ES060_MdlMom_M_6moBF_PFHpA_90 | C25: WaterConc | D25: 20 | E25: 75 | F25: 2025-07-01 | G25: Linear | H25: 0.5 | I25: PFHpA | J25: M | K25: MdlMom | L25: 6 | M25: MoRes
A26: PJ25 | B26: =_xlfn.TEXTJOIN(",",TRUE,Scenario!$A$2:$A$11) -> Set57_ES001_MdlMom_M_6moBF_PFOA_4,Set57_ES002_MdlMom_M_6moBF_PFOA_10,Set57_ES003_MdlMom_M_6moBF_PFOA_20,Set57_ES004_MdlMom_M_6moBF_PFOA_30,Set57_ES005_MdlMom_M_6moBF_PFOA_40,Set57_ES006_MdlMom_M_6moBF_PFOA_50,Set57_ES007_MdlMom_M_6moBF_PFOA_60,Set57_ES008_MdlMom_M_6moBF_PFOA_70,Set57_ES009_MdlMom_M_6moBF_PFOA_80,Set57_ES010_MdlMom_M_6moBF_PFOA_90 | C26: WaterConc | D26: 20 | E26: 75 | F26: 2065-01-01 | G26: Linear | H26: 40 | I26: PFOA | J26: M | K26: MdlMom | L26: 6 | M26: MoRes
A27: PJ26 | B27: =_xlfn.TEXTJOIN(",",TRUE,Scenario!$A$12:$A$21) -> Set57_ES011_MdlMom_M_6moBF_PFOS_4,Set57_ES012_MdlMom_M_6moBF_PFOS_10,Set57_ES013_MdlMom_M_6moBF_PFOS_20,Set57_ES014_MdlMom_M_6moBF_PFOS_30,Set57_ES015_MdlMom_M_6moBF_PFOS_40,Set57_ES016_MdlMom_M_6moBF_PFOS_50,Set57_ES017_MdlMom_M_6moBF_PFOS_60,Set57_ES018_MdlMom_M_6moBF_PFOS_70,Set57_ES019_MdlMom_M_6moBF_PFOS_80,Set57_ES020_MdlMom_M_6moBF_PFOS_90 | C27: WaterConc | D27: 20 | E27: 75 | F27: 2065-01-01 | G27: Linear | H27: 40 | I27: PFOS | J27: M | K27: MdlMom | L27: 6 | M27: MoRes
A28: PJ27 | B28: =_xlfn.TEXTJOIN(",",TRUE,Scenario!$A$22:$A$31) -> Set57_ES021_MdlMom_M_6moBF_PFHxS_4,Set57_ES022_MdlMom_M_6moBF_PFHxS_10,Set57_ES023_MdlMom_M_6moBF_PFHxS_20,Set57_ES024_MdlMom_M_6moBF_PFHxS_30,Set57_ES025_MdlMom_M_6moBF_PFHxS_40,Set57_ES026_MdlMom_M_6moBF_PFHxS_50,Set57_ES027_MdlMom_M_6moBF_PFHxS_60,Set57_ES028_MdlMom_M_6moBF_PFHxS_70,Set57_ES029_MdlMom_M_6moBF_PFHxS_80,Set57_ES030_MdlMom_M_6moBF_PFHxS_90 | C28: WaterConc | D28: 20 | E28: 75 | F28: 2065-01-01 | G28: Linear | H28: 40 | I28: PFHxS | J28: M | K28: MdlMom | L28: 6 | M28: MoRes
A29: PJ28 | B29: =_xlfn.TEXTJOIN(",",TRUE,Scenario!$A$32:$A$41) -> Set57_ES031_MdlMom_M_6moBF_PFNA_4,Set57_ES032_MdlMom_M_6moBF_PFNA_10,Set57_ES033_MdlMom_M_6moBF_PFNA_20,Set57_ES034_MdlMom_M_6moBF_PFNA_30,Set57_ES035_MdlMom_M_6moBF_PFNA_40,Set57_ES036_MdlMom_M_6moBF_PFNA_50,Set57_ES037_MdlMom_M_6moBF_PFNA_60,Set57_ES038_MdlMom_M_6moBF_PFNA_70,Set57_ES039_MdlMom_M_6moBF_PFNA_80,Set57_ES040_MdlMom_M_6moBF_PFNA_90 | C29: WaterConc | D29: 20 | E29: 75 | F29: 2065-01-01 | G29: Linear | H29: 40 | I29: PFNA | J29: M | K29: MdlMom | L29: 6 | M29: MoRes
A30: PJ29 | B30: =_xlfn.TEXTJOIN(",",TRUE,Scenario!$A$42:$A$51) -> Set57_ES041_MdlMom_M_6moBF_PFDA_4,Set57_ES042_MdlMom_M_6moBF_PFDA_10,Set57_ES043_MdlMom_M_6moBF_PFDA_20,Set57_ES044_MdlMom_M_6moBF_PFDA_30,Set57_ES045_MdlMom_M_6moBF_PFDA_40,Set57_ES046_MdlMom_M_6moBF_PFDA_50,Set57_ES047_MdlMom_M_6moBF_PFDA_60,Set57_ES048_MdlMom_M_6moBF_PFDA_70,Set57_ES049_MdlMom_M_6moBF_PFDA_80,Set57_ES050_MdlMom_M_6moBF_PFDA_90 | C30: WaterConc | D30: 20 | E30: 75 | F30: 2065-01-01 | G30: Linear | H30: 40 | I30: PFDA | J30: M | K30: MdlMom | L30: 6 | M30: MoRes
A31: PJ30 | B31: =_xlfn.TEXTJOIN(",",TRUE,Scenario!$A$52:$A$61) -> Set57_ES051_MdlMom_M_6moBF_PFHpA_4,Set57_ES052_MdlMom_M_6moBF_PFHpA_10,Set57_ES053_MdlMom_M_6moBF_PFHpA_20,Set57_ES054_MdlMom_M_6moBF_PFHpA_30,Set57_ES055_MdlMom_M_6moBF_PFHpA_40,Set57_ES056_MdlMom_M_6moBF_PFHpA_50,Set57_ES057_MdlMom_M_6moBF_PFHpA_60,Set57_ES058_MdlMom_M_6moBF_PFHpA_70,Set57_ES059_MdlMom_M_6moBF_PFHpA_80,Set57_ES060_MdlMom_M_6moBF_PFHpA_90 | C31: WaterConc | D31: 20 | E31: 75 | F31: 2065-01-01 | G31: Linear | H31: 40 | I31: PFHpA | J31: M | K31: MdlMom | L31: 6 | M31: MoRes
A32: PJ31 | B32: =_xlfn.TEXTJOIN(",",TRUE,Scenario!$A$2:$A$11) -> Set57_ES001_MdlMom_M_6moBF_PFOA_4,Set57_ES002_MdlMom_M_6moBF_PFOA_10,Set57_ES003_MdlMom_M_6moBF_PFOA_20,Set57_ES004_MdlMom_M_6moBF_PFOA_30,Set57_ES005_MdlMom_M_6moBF_PFOA_40,Set57_ES006_MdlMom_M_6moBF_PFOA_50,Set57_ES007_MdlMom_M_6moBF_PFOA_60,Set57_ES008_MdlMom_M_6moBF_PFOA_70,Set57_ES009_MdlMom_M_6moBF_PFOA_80,Set57_ES010_MdlMom_M_6moBF_PFOA_90 | C32: WaterConc | D32: 20 | E32: 75 | F32: 2095-01-01 | G32: Linear | H32: 70 | I32: PFOA | J32: M | K32: MdlMom | L32: 6 | M32: MoRes
A33: PJ32 | B33: =_xlfn.TEXTJOIN(",",TRUE,Scenario!$A$12:$A$21) -> Set57_ES011_MdlMom_M_6moBF_PFOS_4,Set57_ES012_MdlMom_M_6moBF_PFOS_10,Set57_ES013_MdlMom_M_6moBF_PFOS_20,Set57_ES014_MdlMom_M_6moBF_PFOS_30,Set57_ES015_MdlMom_M_6moBF_PFOS_40,Set57_ES016_MdlMom_M_6moBF_PFOS_50,Set57_ES017_MdlMom_M_6moBF_PFOS_60,Set57_ES018_MdlMom_M_6moBF_PFOS_70,Set57_ES019_MdlMom_M_6moBF_PFOS_80,Set57_ES020_MdlMom_M_6moBF_PFOS_90 | C33: WaterConc | D33: 20 | E33: 75 | F33: 2095-01-01 | G33: Linear | H33: 70 | I33: PFOS | J33: M | K33: MdlMom | L33: 6 | M33: MoRes
A34: PJ33 | B34: =_xlfn.TEXTJOIN(",",TRUE,Scenario!$A$22:$A$31) -> Set57_ES021_MdlMom_M_6moBF_PFHxS_4,Set57_ES022_MdlMom_M_6moBF_PFHxS_10,Set57_ES023_MdlMom_M_6moBF_PFHxS_20,Set57_ES024_MdlMom_M_6moBF_PFHxS_30,Set57_ES025_MdlMom_M_6moBF_PFHxS_40,Set57_ES026_MdlMom_M_6moBF_PFHxS_50,Set57_ES027_MdlMom_M_6moBF_PFHxS_60,Set57_ES028_MdlMom_M_6moBF_PFHxS_70,Set57_ES029_MdlMom_M_6moBF_PFHxS_80,Set57_ES030_MdlMom_M_6moBF_PFHxS_90 | C34: WaterConc | D34: 20 | E34: 75 | F34: 2095-01-01 | G34: Linear | H34: 70 | I34: PFHxS | J34: M | K34: MdlMom | L34: 6 | M34: MoRes
A35: PJ34 | B35: =_xlfn.TEXTJOIN(",",TRUE,Scenario!$A$32:$A$41) -> Set57_ES031_MdlMom_M_6moBF_PFNA_4,Set57_ES032_MdlMom_M_6moBF_PFNA_10,Set57_ES033_MdlMom_M_6moBF_PFNA_20,Set57_ES034_MdlMom_M_6moBF_PFNA_30,Set57_ES035_MdlMom_M_6moBF_PFNA_40,Set57_ES036_MdlMom_M_6moBF_PFNA_50,Set57_ES037_MdlMom_M_6moBF_PFNA_60,Set57_ES038_MdlMom_M_6moBF_PFNA_70,Set57_ES039_MdlMom_M_6moBF_PFNA_80,Set57_ES040_MdlMom_M_6moBF_PFNA_90 | C35: WaterConc | D35: 20 | E35: 75 | F35: 2095-01-01 | G35: Linear | H35: 70 | I35: PFNA | J35: M | K35: MdlMom | L35: 6 | M35: MoRes
A36: PJ35 | B36: =_xlfn.TEXTJOIN(",",TRUE,Scenario!$A$42:$A$51) -> Set57_ES041_MdlMom_M_6moBF_PFDA_4,Set57_ES042_MdlMom_M_6moBF_PFDA_10,Set57_ES043_MdlMom_M_6moBF_PFDA_20,Set57_ES044_MdlMom_M_6moBF_PFDA_30,Set57_ES045_MdlMom_M_6moBF_PFDA_40,Set57_ES046_MdlMom_M_6moBF_PFDA_50,Set57_ES047_MdlMom_M_6moBF_PFDA_60,Set57_ES048_MdlMom_M_6moBF_PFDA_70,Set57_ES049_MdlMom_M_6moBF_PFDA_80,Set57_ES050_MdlMom_M_6moBF_PFDA_90 | C36: WaterConc | D36: 20 | E36: 75 | F36: 2095-01-01 | G36: Linear | H36: 70 | I36: PFDA | J36: M | K36: MdlMom | L36: 6 | M36: MoRes
A37: PJ36 | B37: =_xlfn.TEXTJOIN(",",TRUE,Scenario!$A$52:$A$61) -> Set57_ES051_MdlMom_M_6moBF_PFHpA_4,Set57_ES052_MdlMom_M_6moBF_PFHpA_10,Set57_ES053_MdlMom_M_6moBF_PFHpA_20,Set57_ES054_MdlMom_M_6moBF_PFHpA_30,Set57_ES055_MdlMom_M_6moBF_PFHpA_40,Set57_ES056_MdlMom_M_6moBF_PFHpA_50,Set57_ES057_MdlMom_M_6moBF_PFHpA_60,Set57_ES058_MdlMom_M_6moBF_PFHpA_70,Set57_ES059_MdlMom_M_6moBF_PFHpA_80,Set57_ES060_MdlMom_M_6moBF_PFHpA_90 | C37: WaterConc | D37: 20 | E37: 75 | F37: 2095-01-01 | G37: Linear | H37: 70 | I37: PFHpA | J37: M | K37: MdlMom | L37: 6 | M37: MoRes
A38: PJ37 | B38: =_xlfn.TEXTJOIN(",",TRUE,Scenario!$A$2:$A$11) -> Set57_ES001_MdlMom_M_6moBF_PFOA_4,Set57_ES002_MdlMom_M_6moBF_PFOA_10,Set57_ES003_MdlMom_M_6moBF_PFOA_20,Set57_ES004_MdlMom_M_6moBF_PFOA_30,Set57_ES005_MdlMom_M_6moBF_PFOA_40,Set57_ES006_MdlMom_M_6moBF_PFOA_50,Set57_ES007_MdlMom_M_6moBF_PFOA_60,Set57_ES008_MdlMom_M_6moBF_PFOA_70,Set57_ES009_MdlMom_M_6moBF_PFOA_80,Set57_ES010_MdlMom_M_6moBF_PFOA_90 | C38: WaterConc | D38: 20 | E38: 50 | F38: 2025-07-01 | G38: Linear | H38: 0.5 | I38: PFOA | J38: M | K38: MdlMom | L38: 6 | M38: MoRes
A39: PJ38 | B39: =_xlfn.TEXTJOIN(",",TRUE,Scenario!$A$12:$A$21) -> Set57_ES011_MdlMom_M_6moBF_PFOS_4,Set57_ES012_MdlMom_M_6moBF_PFOS_10,Set57_ES013_MdlMom_M_6moBF_PFOS_20,Set57_ES014_MdlMom_M_6moBF_PFOS_30,Set57_ES015_MdlMom_M_6moBF_PFOS_40,Set57_ES016_MdlMom_M_6moBF_PFOS_50,Set57_ES017_MdlMom_M_6moBF_PFOS_60,Set57_ES018_MdlMom_M_6moBF_PFOS_70,Set57_ES019_MdlMom_M_6moBF_PFOS_80,Set57_ES020_MdlMom_M_6moBF_PFOS_90 | C39: WaterConc | D39: 20 | E39: 50 | F39: 2025-07-01 | G39: Linear | H39: 0.5 | I39: PFOS | J39: M | K39: MdlMom | L39: 6 | M39: MoRes
A40: PJ39 | B40: =_xlfn.TEXTJOIN(",",TRUE,Scenario!$A$22:$A$31) -> Set57_ES021_MdlMom_M_6moBF_PFHxS_4,Set57_ES022_MdlMom_M_6moBF_PFHxS_10,Set57_ES023_MdlMom_M_6moBF_PFHxS_20,Set57_ES024_MdlMom_M_6moBF_PFHxS_30,Set57_ES025_MdlMom_M_6moBF_PFHxS_40,Set57_ES026_MdlMom_M_6moBF_PFHxS_50,Set57_ES027_MdlMom_M_6moBF_PFHxS_60,Set57_ES028_MdlMom_M_6moBF_PFHxS_70,Set57_ES029_MdlMom_M_6moBF_PFHxS_80,Set57_ES030_MdlMom_M_6moBF_PFHxS_90 | C40: WaterConc | D40: 20 | E40: 50 | F40: 2025-07-01 | G40: Linear | H40: 0.5 | I40: PFHxS | J40: M | K40: MdlMom | L40: 6 | M40: MoRes
...

Sheet AgeInfo
A1: FileGroup | B1: MinAge | C1: MaxAge | D1: Fraction | E1: Distribution | F1: Param1 | G1: Param2 | H1: Param3
A2: RonnebySE_adults.loexp | B2: 0 | C2: 10 | D2: 0.103 | E2: Uniform | F2: =B2 -> 0 | G2: =C2+1 -> 11
A3: RonnebySE_adults.loexp | B3: 11 | C3: 20 | D3: 0.103 | E3: Uniform | F3: =B3 -> 11 | G3: =C3+1 -> 21
A4: RonnebySE_adults.loexp | B4: 21 | C4: 30 | D4: 0.104 | E4: Uniform | F4: =B4 -> 21 | G4: =C4+1 -> 31
A5: RonnebySE_adults.loexp | B5: 31 | C5: 40 | D5: 0.141 | E5: Uniform | F5: =B5 -> 31 | G5: =C5+1 -> 41
A6: RonnebySE_adults.loexp | B6: 41 | C6: 50 | D6: 0.187 | E6: Uniform | F6: =B6 -> 41 | G6: =C6+1 -> 51
A7: RonnebySE_adults.loexp | B7: 51 | C7: 60 | D7: 0.143 | E7: Uniform | F7: =B7 -> 51 | G7: =C7+1 -> 61
A8: RonnebySE_adults.loexp | B8: 61 | C8: 70 | D8: 0.139 | E8: Uniform | F8: =B8 -> 61 | G8: =C8+1 -> 71
A9: RonnebySE_adults.loexp | B9: 71 | C9: 99 | E9: Triangular | F9: =B9 -> 71 | G9: =C9+1 -> 100 | H9: =B9+0.1 -> 71.1
A10: ArnsbergDE_children | B10: 5 | C10: 6 | D10: 1 | E10: Uniform | F10: =B10 -> 5 | G10: =C10+1 -> 7
A11: ArnsbergDE_women | B11: 23 | C11: 49 | D11: 1 | E11: Uniform | F11: =B11 -> 23 | G11: =C11+1 -> 50
A12: ArnsbergDE_men | B12: 18 | C12: 69 | D12: 1 | E12: Uniform | F12: =B12 -> 18 | G12: =C12+1 -> 70
A13: GustavusUS_adults | B13: 8 | C13: 17 | D13: 0.22 | E13: Uniform | F13: =B13 -> 8 | G13: =C13+1 -> 18
A14: GustavusUS_adults | B14: 18 | C14: 32 | D14: 0.08 | E14: Uniform | F14: =B14 -> 18 | G14: =C14+1 -> 33
A15: GustavusUS_adults | B15: 33 | C15: 69 | D15: 0.65 | E15: Uniform | F15: =B15 -> 33 | G15: =C15+1 -> 70
A16: GustavusUS_adults | B16: 70 | C16: 97 | E16: Triangular | F16: =B16 -> 70 | G16: =C16+1 -> 98 | H16: =B16+0.1 -> 70.1
A17: MaineUS_adults | B17: 18 | C17: 40 | D17: 0.03 | E17: Uniform | F17: =B17 -> 18 | G17: =C17+1 -> 41
A18: MaineUS_adults | B18: 41 | C18: 60 | D18: 0.2 | E18: Uniform | F18: =B18 -> 41 | G18: =C18+1 -> 61
A19: MaineUS_adults | B19: 61 | C19: 70 | D19: 0.516 | E19: Uniform | F19: =B19 -> 61 | G19: =C19+1 -> 71
A20: MaineUS_adults | B20: 71 | C20: 80 | E20: Triangular | F20: =B20 -> 71 | G20: =C20+1 -> 81 | H20: =B20+0.1 -> 71.1
A21: PittsboroUS_adults | B21: 30 | C21: 39 | D21: 0.16 | E21: Uniform | F21: =B21 -> 30 | G21: =C21+1 -> 40
A22: PittsboroUS_adults | B22: 40 | C22: 49 | D22: 0.16 | E22: Uniform | F22: =B22 -> 40 | G22: =C22+1 -> 50
A23: PittsboroUS_adults | B23: 50 | C23: 59 | D23: 0.2 | E23: Uniform | F23: =B23 -> 50 | G23: =C23+1 -> 60
A24: PittsboroUS_adults | B24: 60 | C24: 69 | D24: 0.18 | E24: Uniform | F24: =B24 -> 60 | G24: =C24+1 -> 70
A25: PittsboroUS_adults | B25: 70 | C25: 79 | D25: 0.24 | E25: Uniform | F25: =B25 -> 70 | G25: =C25+1 -> 80
A26: PittsboroUS_adults | B26: 80 | C26: 99 | E26: Triangular | F26: =B26 -> 80 | G26: =C26 -> 99 | H26: =B26+0.1 -> 80.1

Sheet MonteCarlo
A1: Chemical | B1: Variable | C1: Mean | D1: Sd | E1: sd_multiplier | F1: Distribution
A2: PFOA | B2: HalfLife | C2: 3.14 | D2: 1.57 | E2: NA | F2: Lognormal_geommean
A3: PFOS | B3: HalfLife | C3: 3.36 | D3: 1.57 | E3: NA | F3: Lognormal_geommean
A4: PFHxS | B4: HalfLife | C4: 8.3 | D4: 1.57 | E4: NA | F4: Lognormal_geommean
A5: PFNA | B5: HalfLife | C5: 2.35 | D5: 1.53 | E5: NA | F5: Lognormal_geommean
A6: PFDA | B6: HalfLife | C6: 4.72 | D6: 1.57 | E6: NA | F6: Lognormal_geommean
A7: PFHpA | B7: HalfLife | C7: 0.384 | D7: 1.57 | E7: NA | F7: Lognormal_geommean
A8: PFOA | B8: VolDist | C8: 0.428 | D8: 1.12 | E8: NA | F8: Lognormal_geommean
A9: PFOS | B9: VolDist | C9: 0.32 | D9: 1.11 | E9: NA | F9: Lognormal_geommean
A10: PFHxS | B10: VolDist | C10: 0.29 | D10: 1.11 | E10: NA | F10: Lognormal_geommean
A11: PFNA | B11: VolDist | C11: 0.19 | D11: 1.12 | E11: NA | F11: Lognormal_geommean
A12: PFDA | B12: VolDist | C12: 0.365 | D12: 1.12 | E12: NA | F12: Lognormal_geommean
A13: PFHpA | B13: VolDist | C13: 0.21 | D13: 1.12 | E13: NA | F13: Lognormal_geommean
... A16: NA | B16: DWIaf_Teen | C16: 0.88 | D16: 0.87 | E16: NA | F16: Gamma
A17: PFOA | B17: PlacXfer | C17: 0.87 | D17: =C17*E17 -> 0.0174 | E17: 0.02 | F17: Normal
A18: PFOS | B18: PlacXfer | C18: 0.42 | D18: =C18*E18 -> 0.0084 | E18: 0.02 | F18: Normal
A19: PFHxS | B19: PlacXfer | C19: 0.7 | D19: =C19*E19 -> 0.014 | E19: 0.02 | F19: Normal
A20: PFNA | B20: PlacXfer | C20: 0.53 | D20: =C20*E20 -> 0.0106 | E20: 0.02 | F20: Normal
A21: PFDA | B21: PlacXfer | C21: 0.32 | D21: =C21*E21 -> 0.0064 | E21: 0.02 | F21: Normal
A22: PFHpA | B22: PlacXfer | C22: 1.25 | D22: =C22*E22 -> 0.025 | E22: 0.02 | F22: Normal
A23: PFOA | B23: LactXfer | C23: 0.052 | D23: =C23*E23 -> 0.00104 | E23: 0.02 | F23: Normal
A24: PFOS | B24: LactXfer | C24: 0.013 | D24: =C24*E24 -> 0.00026 | E24: 0.02 | F24: Normal
A25: PFHxS | B25: LactXfer | C25: 0.014 | D25: =C25*E25 -> 0.00028 | E25: 0.02 | F25: Normal
A26: PFNA | B26: LactXfer | C26: 0.01 | D26: =C26*E26 -> 0.0002 | E26: 0.02 | F26: Normal
A27: PFDA | B27: LactXfer | C27: 0.023 | D27: =C27*E27 -> 0.00046 | E27: 0.02 | F27: Normal
A28: PFHpA | B28: LactXfer | C28: 0.052 | D28: =C28*E28 -> 0.00104 | E28: 0.02 | F28: Normal
A29: PFOA | B29: kMilk | C29: 0.00426 | D29: NA | E29: NA | F29: None
A30: PFOS | B30: kMilk | C30: 0.00199 | D30: NA | E30: NA | F30: None
A31: PFHxS | B31: kMilk | C31: 0.000844 | D31: NA | E31: NA | F31: None
A32: PFNA | B32: kMilk | C32: 0.000911 | D32: NA | E32: NA | F32: None
A33: PFDA | B33: kMilk | C33: 0.0021 | D33: NA | E33: NA | F33: None
A34: PFHpA | B34: kMilk | C34: 0.00426 | D34: NA | E34: NA | F34: None
A35: NA | B35: BirthLoss | C35: 0 | D35: NA | E35: NA | F35: None

Sheet DWI
A1: Age_Years | B1: DWI_mL_kg_d | C1: EFH_bin
A2: 0 | B2: 150 | C2: 0 to <1 months
A3: 0.083 | B3: 140 | C3: 1 to <3 months
A4: 0.167 | B4: 140
A5: 0.25 | B5: 110 | C5: 3 to <6 months
A6: 0.333 | B6: 110
A7: 0.417 | B7: 110
A8: 0.5 | B8: 83 | C8: 6 to <12 months
A9: 0.583 | B9: 83
A10: 0.667 | B10: 83
A11: 0.75 | B11: 83
A12: 0.833 | B12: 83
A13: 0.917 | B13: 83
A14: 1 | B14: 22.1 | C14: 1 to <2 years
A15: 2 | B15: 23.9 | C15: 2 to <3 years
A16: 3 | B16: =B15+($B$15-$B$18)/($A$15-$A$18) -> 22.17
A17: 4 | B17: =B16+($B$15-$B$18)/($A$15-$A$18) -> 20.44
A18: 5 | B18: 18.7 | C18: 3 to <6 years
A19: 6 | B19: =B18+($B$18-$B$23)/($A$18-$A$23) -> 18
A20: 7 | B20: =B19+($B$18-$B$23)/($A$18-$A$23) -> 17.3
A21: 8 | B21: =B20+($B$18-$B$23)/($A$18-$A$23) -> 16.6
A22: 9 | B22: =B21+($B$18-$B$23)/($A$18-$A$23) -> 15.9
A23: 10 | B23: 15.2 | C23: 6 to <11 years
A24: 11 | B24: =B23+($B$23-$B$28)/($A$23-$A$28) -> 14.24
A25: =A24+1 -> 12 | B25: =B24+($B$23-$B$28)/($A$23-$A$28) -> 13.28
A26: =A25+1 -> 13 | B26: =B25+($B$23-$B$28)/($A$23-$A$28) -> 12.32
A27: =A26+1 -> 14 | B27: =B26+($B$23-$B$28)/($A$23-$A$28) -> 11.36
A28: =A27+1 -> 15 | B28: 10.4 | C28: 11 to <16 years
A29: =A28+1 -> 16 | B29: =B28+($B$28-$B$33)/($A$28-$A$33) -> 10.36
A30: =A29+1 -> 17 | B30: =B29+($B$28-$B$33)/($A$28-$A$33) -> 10.32
A31: =A30+1 -> 18 | B31: =B30+($B$28-$B$33)/($A$28-$A$33) -> 10.28
A32: =A31+1 -> 19 | B32: =B31+($B$28-$B$33)/($A$28-$A$33) -> 10.24
A33: =A32+1 -> 20 | B33: 10.2 | C33: 16 to <21 years
A34: =A33+1 -> 21 | B34: =B33+($B$33-$B$42)/($A$33-$A$42) -> 10.83
A35: =A34+1 -> 22 | B35: =B34+($B$33-$B$42)/($A$33-$A$42) -> 11.46
A36: =A35+1 -> 23 | B36: =B35+($B$33-$B$42)/($A$33-$A$42) -> 12.09
A37: =A36+1 -> 24 | B37: =B36+($B$33-$B$42)/($A$33-$A$42) -> 12.72
A38: =A37+1 -> 25 | B38: =B37+($B$33-$B$42)/($A$33-$A$42) -> 13.35
A39: =A38+1 -> 26 | B39: =B38+($B$33-$B$42)/($A$33-$A$42) -> 13.98
A40: =A39+1 -> 27 | B40: =B39+($B$33-$B$42)/($A$33-$A$42) -> 14.61
...

Sheet BkgdSerum
A1: Chemical | B1: StartDate | C1: BkgdFA_Mean | D1: BkgdFA_Sd | E1: BkgdMA_Mean | F1: BkgdMA_Sd | G1: BkgdUA_Mean | H1: BkgdUA_Sd | I1: BkgdFC_Mean | J1: BkgdFC_Sd | K1: BkgdMC_Mean | L1: BkgdMC_Sd | M1: BkgdUC_Mean | N1: BkgdUC_Sd | O1: Distribution
A2: PFOA | B2: 1850-01-01 | C2: 0 | D2: 0 | E2: 0 | F2: 0 | G2: 0 | H2: 0 | I2: 0 | J2: 0 | K2: 0 | L2: 0 | M2: 0 | N2: 0 | O2: None
A3: PFOS | B3: 1850-01-01 | C3: 0 | D3: 0 | E3: 0 | F3: 0 | G3: 0 | H3: 0 | I3: 0 | J3: 0 | K3: 0 | L3: 0 | M3: 0 | N3: 0 | O3: None
A4: PFDA | B4: 1850-01-01 | C4: 0 | D4: 0 | E4: 0 | F4: 0 | G4: 0 | H4: 0 | I4: 0 | J4: 0 | K4: 0 | L4: 0 | M4: 0 | N4: 0 | O4: None
A5: PFHpA | B5: 1850-01-01 | C5: 0 | D5: 0 | E5: 0 | F5: 0 | G5: 0 | H5: 0 | I5: 0 | J5: 0 | K5: 0 | L5: 0 | M5: 0 | N5: 0 | O5: None
A6: PFHxS | B6: 1850-01-01 | C6: 0 | D6: 0 | E6: 0 | F6: 0 | G6: 0 | H6: 0 | I6: 0 | J6: 0 | K6: 0 | L6: 0 | M6: 0 | N6: 0 | O6: None
A7: PFNA | B7: 1850-01-01 | C7: 0 | D7: 0 | E7: 0 | F7: 0 | G7: 0 | H7: 0 | I7: 0 | J7: 0 | K7: 0 | L7: 0 | M7: 0 | N7: 0 | O7: None
A8: PFOA | B8: 1960-01-01 | C8: 1.2624842 | D8: 1.9625904 | E8: 1.6070604 | F8: 1.7460773 | G8: =AVERAGE(C8,E8) -> 1.4347723 | H8: =MAX(D8,F8) -> 1.9625904 | I8: 1.8968102 | J8: 1.5776126 | K8: 1.9461782 | L8: 1.6706924 | M8: =AVERAGE(I8,K8) -> 1.9214942 | N8: =MAX(J8,L8) -> 1.6706924 | O8: Lognormal_geommean
A9: PFOS | B9: 1960-01-01 | C9: 3.414556 | D9: 1.7787044 | E9: 5.3626243 | F9: 1.6315804 | G9: =AVERAGE(C9,E9) -> 4.3885902 | H9: =MAX(D9,F9) -> 1.7787044 | I9: 3.6990683 | J9: 1.6423399 | K9: 4.0677075 | L9: 1.9103372 | M9: =AVERAGE(I9,K9) -> 3.8833879 | N9: =MAX(J9,L9) -> 1.9103372 | O9: Lognormal_geommean
A10: PFDA | B10: 1960-01-01 | C10: 0.196 | D10: 2.046 | E10: 0.19 | F10: 1.86 | G10: =AVERAGE(C10,E10) -> 0.193 | H10: =MAX(D10,F10) -> 2.046 | I10: 0.1 | J10: 2.379 | K10: 0.0719 | L10: 3.003 | M10: =AVERAGE(I10,K10) -> 0.08595 | N10: =MAX(J10,L10) -> 3.003 | O10: Lognormal_geommean
A11: PFHpA | B11: 1960-01-01 | C11: 0.071 | D11: 1.665 | E11: 0.071 | F11: 1.665 | G11: =AVERAGE(C11,E11) -> 0.071 | H11: =MAX(D11,F11) -> 1.665 | I11: 0.034 | J11: 3.164 | K11: 0.035 | L11: 2.91 | M11: =AVERAGE(I11,K11) -> 0.0345 | N11: =MAX(J11,L11) -> 3.164 | O11: Lognormal_geommean
A12: PFHxS | B12: 1960-01-01 | C12: 0.80508207 | D12: 1.8130287 | E12: 1.483323 | F12: 2.1492767 | G12: =AVERAGE(C12,E12) -> 1.1442025 | H12: =MAX(D12,F12) -> 2.1492767 | I12: 0.75690474 | J12: 1.9414576 | K12: 0.93324918 | L12: 2.1744486 | M12: =AVERAGE(I12,K12) -> 0.84507696 | N12: =MAX(J12,L12) -> 2.1744486 | O12: Lognormal_geommean
A13: PFNA | B13: 1960-01-01 | C13: 0.38356235 | D13: 1.6304535 | E13: 0.44166417 | F13: 1.6409597 | G13: =AVERAGE(C13,E13) -> 0.41261326 | H13: =MAX(D13,F13) -> 1.6409597 | I13: 0.75881872 | J13: 1.8434731 | K13: 0.82903704 | L13: 2.1454059 | M13: =AVERAGE(I13,K13) -> 0.79392788 | N13: =MAX(J13,L13) -> 2.1454059 | O13: Lognormal_geommean

Sheet MatSerum
A1: ParmType | B1: Chemical | C1: WaterID | D1: meanlog | E1: sdlog | F1: Distribution | G1: SourceModel
A2: BkgdSerum | B2: PFOA | C2: NA | D2: 1.2624842 | E2: 1.9625904 | F2: Lognormal_geommean | G2: NA
A3: BkgdSerum | B3: PFOS | C3: NA | D3: 3.414556 | E3: 1.7787044 | F3: Lognormal_geommean | G3: NA
A4: BkgdSerum | B4: PFDA | C4: NA | D4: 0.196 | E4: 2.046 | F4: Lognormal_geommean | G4: NA
A5: BkgdSerum | B5: PFHpA | C5: NA | D5: 0.071 | E5: 1.665 | F5: Lognormal_geommean | G5: NA
A6: BkgdSerum | B6: PFHxS | C6: NA | D6: 0.80508207 | E6: 1.8130287 | F6: Lognormal_geommean | G6: NA
A7: BkgdSerum | B7: PFNA | C7: NA | D7: 0.38356235 | E7: 1.6304535 | F7: Lognormal_geommean | G7: NA
A8: TotalSerum | B8: PFOS | C8: FrommePop | D8: 1.1631507 | E8: 0.39221527 | F8: Lognormal_meanlog | G8: Fromme2010
A9: TotalSerum | B9: PFOA | C9: FrommePop | D9: 0.64185385 | E9: 0.61209324 | F9: Lognormal_meanlog | G9: Fromme2010
A10: TotalSerum | B10: PFHxS | C10: FrommePop | D10: -0.69314501 | E10: 0.66790944 | F10: Lognormal_meanlog | G10: Fromme2010
A11: TotalSerum | B11: PFNA | C11: FrommePop | D11: -0.51080124 | E11: 0.97838302 | F11: Lognormal_meanlog | G11: Fromme2010
A12: TotalSerum | B12: PFOA | C12: VarsiPop | D12: -0.06 | E12: 0.43 | F12: Lognormal_meanlog | G12: Varsi2022
A13: TotalSerum | B13: PFNA | C13: VarsiPop | D13: -0.96 | E13: 0.32 | F13: Lognormal_meanlog | G13: Varsi2022
... A16: TotalSerum | B16: PFOS | C16: VarsiPop | D16: 1.36 | E16: 0.42 | F16: Lognormal_meanlog | G16: Varsi2022

Sheet AltParams
A1: ScenarioID | B1: Variable | C1: Parm1_Mean | D1: Parm2_Sd | E1: Parm3 | F1: Distribution

Sheet EvalInfo
A1: ScenID | B1: Date | C1: Metrics | D1: Values | E1: ParmType | F1: StudyLoc | G1: DemoGroup | H1: Chemical | I1: SampleSize | J1: SampleSizeGroup | K1: ObservationToCompare
